<?xml version="1.0" ?>
<robot name="converted_robot">
   <link name="world">
      <inertial>
         <origin xyz="0.0 0.0 0.0" rpy="0.0 0.0 0.0"/>
         <mass value="0.0"/>
         <inertia ixx="0.0" iyy="0.0" izz="0.0" ixy="0" ixz="0" iyz="0"/>
      </inertial>
   </link>
   <link name="root">
      <inertial>
         <origin xyz="0.04161047529095292 -6.509963065670219e-05 0.0006405320577736168" rpy="1.601756256288497 0.0003577336710351986 1.5696885660684892"/>
         <mass value="1.2601437096752013"/>
         <inertia ixx="0.0035950464418034005" iyy="0.003407421321228048" izz="0.0008540608341563234" ixy="0" ixz="0" iyz="0"/>
      </inertial>
      <visual name="tower">
         <origin xyz="0.036751331386063464 -7.220944867772884e-05 0.0006808335860844365" rpy="1.605818097654102 -0.00012196279526488496 1.5691792722553257"/>
         <geometry>
            <mesh filename="package://dextrous_hand/data/assets/urdf/converted_tower.stl"/>
         </geometry>
         <material name="white"/>
      </visual>
      <visual name="to_tower">
         <origin xyz="0.11395128774936551 4.07482351690025e-05 4.054050403783094e-05" rpy="-0.0015950895409915233 -0.0007964483488058782 -7.632304084337349e-05"/>
         <geometry>
            <mesh filename="package://dextrous_hand/data/assets/urdf/converted_to_tower.stl"/>
         </geometry>
         <material name="white"/>
      </visual>
   </link>
   <link name="world2root_fixed_jointbody">
      <inertial>
         <origin xyz="0.0 0.0 0.0" rpy="0.0 0.0 0.0"/>
         <mass value="0.001"/>
         <inertia ixx="1e-09" iyy="1e-09" izz="1e-09" ixy="0" ixz="0" iyz="0"/>
      </inertial>
   </link>
   <joint type="fixed" name="world2root_fixed">
      <parent link="world"/>
      <child link="world2root_fixed_jointbody"/>
      <origin xyz="0.0 0.0 0.0" rpy="-0.7853981610777355 -1.5706601001352392 -0.7853981610777355"/>
   </joint>
   <joint type="fixed" name="world2root_fixed_offset">
      <parent link="world2root_fixed_jointbody"/>
      <child link="root"/>
      <origin xyz="-0.0 -0.0 -0.0" rpy="0.0 0.0 0.0"/>
   </joint>
   <link name="palm">
      <inertial>
         <origin xyz="-0.00234180369363099 -0.008707331059203707 -6.55854985490824e-05" rpy="2.2686960813272683 -1.5628450264847862 -0.8023523734276821"/>
         <mass value="0.15771589069643427"/>
         <inertia ixx="0.00017296082707011102" iyy="0.0001019615404014643" izz="7.65142954592705e-05" ixy="0" ixz="0" iyz="0"/>
      </inertial>
      <visual name="palm">
         <origin xyz="-0.0015958827971541678 -0.00395752856644533 -0.0002967050081316631" rpy="2.409834578729982 -1.5643178390026542 0.9171752837278707"/>
         <geometry>
            <mesh filename="package://dextrous_hand/data/assets/urdf/converted_palm.stl"/>
         </geometry>
         <material name="white"/>
      </visual>
      <visual name="to_hand">
         <origin xyz="-0.0022635428276815348 -0.04308378604823335 -3.878215645104852e-05" rpy="2.7188854293849607 -1.5690598340634987 -2.730067789044118"/>
         <geometry>
            <mesh filename="package://dextrous_hand/data/assets/urdf/converted_to_hand.stl"/>
         </geometry>
         <material name="white"/>
      </visual>
      <visual name="index_mc_add">
         <origin xyz="0.02596797067460067 0.03317171598066676 0.001629031798226111" rpy="-3.110943274125341 1.287685593281557 -1.569305965587619"/>
         <geometry>
            <mesh filename="package://dextrous_hand/data/assets/urdf/converted_index_mc_add.stl"/>
         </geometry>
         <material name="white"/>
      </visual>
      <visual name="middle_mc_add">
         <origin xyz="0.0014096582832805221 0.034561644828078684 0.0016290317415653868" rpy="-3.110772343222124 1.2876840852409521 -1.509141858300692"/>
         <geometry>
            <mesh filename="package://dextrous_hand/data/assets/urdf/converted_middle_mc_add.stl"/>
         </geometry>
         <material name="white"/>
      </visual>
      <visual name="pinky_mc_add">
         <origin xyz="-0.04014575190011041 0.022003144785407873 0.0016290568258307482" rpy="-3.110152980123235 1.2876539473856754 -1.2875472237221097"/>
         <geometry>
            <mesh filename="package://dextrous_hand/data/assets/urdf/converted_pinky_mc_add.stl"/>
         </geometry>
         <material name="white"/>
      </visual>
      <visual name="ring_mc_add">
         <origin xyz="-0.019903640878059934 0.029175741835039237 0.001629035004122498" rpy="-3.1105879047113567 1.2876792151817171 -1.4439647828783166"/>
         <geometry>
            <mesh filename="package://dextrous_hand/data/assets/urdf/converted_ring_mc_add.stl"/>
         </geometry>
         <material name="white"/>
      </visual>
   </link>
   <link name="root2palm_fixed_jointbody">
      <inertial>
         <origin xyz="0.0 0.0 0.0" rpy="0.0 0.0 0.0"/>
         <mass value="0.001"/>
         <inertia ixx="1e-09" iyy="1e-09" izz="1e-09" ixy="0" ixz="0" iyz="0"/>
      </inertial>
   </link>
   <joint type="fixed" name="root2palm_fixed">
      <parent link="root"/>
      <child link="root2palm_fixed_jointbody"/>
      <origin xyz="0.176 -0.0003 0.0019" rpy="-0.7853980048633405 -1.5696701507009854 -0.7853980048633405"/>
   </joint>
   <joint type="fixed" name="root2palm_fixed_offset">
      <parent link="root2palm_fixed_jointbody"/>
      <child link="palm"/>
      <origin xyz="-0.0 -0.0 -0.0" rpy="0.0 0.0 0.0"/>
   </joint>
   <link name="thumb_base">
      <inertial>
         <origin xyz="0.0013685068183649609 0.0028782820340300494 -0.002332579170271435" rpy="1.7011410432022038 -0.5820157407498587 -0.0017162614812410437"/>
         <mass value="0.014795230696981004"/>
         <inertia ixx="2.1513889208321284e-06" iyy="1.8173009156089443e-06" izz="9.58999512607794e-07" ixy="0" ixz="0" iyz="0"/>
      </inertial>
      <visual name="thumb_base">
         <origin xyz="0.0013685068183649609 0.0028782820340300494 -0.002332579170271435" rpy="1.7011410432022038 -0.5820157407498587 -0.0017162614812410437"/>
         <geometry>
            <mesh filename="package://dextrous_hand/data/assets/urdf/converted_thumb_base.stl"/>
         </geometry>
         <material name="white"/>
      </visual>
   </link>
   <link name="root2thumb_base_jointbody">
      <inertial>
         <origin xyz="0.0 0.0 0.0" rpy="0.0 0.0 0.0"/>
         <mass value="0.001"/>
         <inertia ixx="1e-09" iyy="1e-09" izz="1e-09" ixy="0" ixz="0" iyz="0"/>
      </inertial>
   </link>
   <joint type="revolute" name="root2thumb_base">
      <parent link="palm"/>
      <child link="root2thumb_base_jointbody"/>
      <origin xyz="0.0358 -0.008 0.0" rpy="0.0 0.0 -0.1718"/>
      <axis xyz="0.0 -1.0 0.0"/>
      <limit lower="0.0" upper="2.356" effort="100" velocity="100"/>
   </joint>
   <joint type="fixed" name="root2thumb_base_offset">
      <parent link="root2thumb_base_jointbody"/>
      <child link="thumb_base"/>
      <origin xyz="-0.0 -0.0 -0.0" rpy="0.0 0.0 0.0"/>
   </joint>
   <link name="thumb_pp">
      <inertial>
         <origin xyz="-0.0023941734919475104 0.0017121546879330903 -0.014881006402773811" rpy="0.17263985314669741 0.07218436814675355 -0.3517490024915264"/>
         <mass value="0.009291852347820161"/>
         <inertia ixx="1.7569558490119081e-06" iyy="1.6734613230176222e-06" izz="2.777207090264275e-07" ixy="0" ixz="0" iyz="0"/>
      </inertial>
      <visual name="thumb_pp">
         <origin xyz="-0.0023941734919475104 0.0017121546879330903 -0.014881006402773811" rpy="0.17263985314669741 0.07218436814675355 -0.3517490024915264"/>
         <geometry>
            <mesh filename="package://dextrous_hand/data/assets/urdf/converted_thumb_pp.stl"/>
         </geometry>
         <material name="white"/>
      </visual>
   </link>
   <link name="thumb_base2pp_jointbody">
      <inertial>
         <origin xyz="0.0 0.0 0.0" rpy="0.0 0.0 0.0"/>
         <mass value="0.001"/>
         <inertia ixx="1e-09" iyy="1e-09" izz="1e-09" ixy="0" ixz="0" iyz="0"/>
      </inertial>
   </link>
   <joint type="revolute" name="thumb_base2pp">
      <parent link="thumb_base"/>
      <child link="thumb_base2pp_jointbody"/>
      <origin xyz="0.006533598964040238 0.0009856559418268736 0.007298535710728157" rpy="-1.5522799247268875 0.7886936673883342 -1.5522799247268875"/>
      <axis xyz="-0.7071067811865476 -0.7071067811865476 0.0"/>
      <limit lower="0.0" upper="1.48" effort="100" velocity="100"/>
   </joint>
   <joint type="fixed" name="thumb_base2pp_offset">
      <parent link="thumb_base2pp_jointbody"/>
      <child link="thumb_pp"/>
      <origin xyz="0.013 0.0 0.0325" rpy="0.0 0.0 0.0"/>
   </joint>
   <link name="thumb_mp_virt">
      <inertial>
         <origin xyz="0.009525 -0.041187 0.083647" rpy="-0.2229159847709277 -1.2682876286119866 0.3020329839181936"/>
         <mass value="0.001"/>
         <inertia ixx="4e-10" iyy="4e-10" izz="3e-10" ixy="0" ixz="0" iyz="0"/>
      </inertial>
   </link>
   <link name="thumb_pp2mp_virt_jointbody">
      <inertial>
         <origin xyz="0.0 0.0 0.0" rpy="0.0 0.0 0.0"/>
         <mass value="0.001"/>
         <inertia ixx="1e-09" iyy="1e-09" izz="1e-09" ixy="0" ixz="0" iyz="0"/>
      </inertial>
   </link>
   <joint type="revolute" name="thumb_pp2mp_virt">
      <parent link="thumb_pp"/>
      <child link="thumb_pp2mp_virt_jointbody"/>
      <origin xyz="0.0 -0.0065 0.0" rpy="0.0 -1.57 0.0"/>
      <axis xyz="0.0 -1.0 0.0"/>
      <limit lower="0.0" upper="0.96" effort="100" velocity="100"/>
   </joint>
   <joint type="fixed" name="thumb_pp2mp_virt_offset">
      <parent link="thumb_pp2mp_virt_jointbody"/>
      <child link="thumb_mp_virt"/>
      <origin xyz="-0.0 -0.0 -0.0" rpy="0.0 0.0 0.0"/>
   </joint>
   <link name="thumb_mp">
      <inertial>
         <origin xyz="0.010812547508388727 0.006432684742823032 0.0013888625559597815" rpy="-2.6810846553808494 -1.5116584121649967 -0.4551519026519524"/>
         <mass value="0.007189847562119937"/>
         <inertia ixx="9.242712855568975e-07" iyy="8.959671661259627e-07" izz="1.6777768801904529e-07" ixy="0" ixz="0" iyz="0"/>
      </inertial>
      <visual name="thumb_mp">
         <origin xyz="0.010812547508388727 0.006432684742823032 0.0013888625559597815" rpy="-2.681084655380851 -1.5116584121649965 -0.45515190265195105"/>
         <geometry>
            <mesh filename="package://dextrous_hand/data/assets/urdf/converted_thumb_mp.stl"/>
         </geometry>
         <material name="white"/>
      </visual>
   </link>
   <link name="thumb_pp2mp_jointbody">
      <inertial>
         <origin xyz="0.0 0.0 0.0" rpy="0.0 0.0 0.0"/>
         <mass value="0.001"/>
         <inertia ixx="1e-09" iyy="1e-09" izz="1e-09" ixy="0" ixz="0" iyz="0"/>
      </inertial>
   </link>
   <joint type="revolute" name="thumb_pp2mp">
      <parent link="thumb_mp_virt"/>
      <child link="thumb_pp2mp_jointbody"/>
      <origin xyz="0.018 0.0 0.0" rpy="0.0 0.0 0.0"/>
      <axis xyz="0.0 -1.0 0.0"/>
      <limit lower="0.0" upper="0.96" effort="100" velocity="100"/>
   </joint>
   <joint type="fixed" name="thumb_pp2mp_offset">
      <parent link="thumb_pp2mp_jointbody"/>
      <child link="thumb_mp"/>
      <origin xyz="-0.0 -0.0 -0.0" rpy="0.0 0.0 0.0"/>
   </joint>
   <link name="thumb_dp_virt">
      <inertial>
         <origin xyz="0.009403 -0.031797 0.120984" rpy="-0.2229159847709277 -1.2682876286119866 0.3020329839181936"/>
         <mass value="0.001"/>
         <inertia ixx="4e-10" iyy="4e-10" izz="3e-10" ixy="0" ixz="0" iyz="0"/>
      </inertial>
   </link>
   <link name="thumb_mp2dp_virt_jointbody">
      <inertial>
         <origin xyz="0.0 0.0 0.0" rpy="0.0 0.0 0.0"/>
         <mass value="0.001"/>
         <inertia ixx="1e-09" iyy="1e-09" izz="1e-09" ixy="0" ixz="0" iyz="0"/>
      </inertial>
   </link>
   <joint type="revolute" name="thumb_mp2dp_virt">
      <parent link="thumb_mp"/>
      <child link="thumb_mp2dp_virt_jointbody"/>
      <origin xyz="0.026 0.0 0.0" rpy="0.0 0.0 0.0"/>
      <axis xyz="0.0 -1.0 0.0"/>
      <limit lower="0.0" upper="0.68" effort="100" velocity="100"/>
   </joint>
   <joint type="fixed" name="thumb_mp2dp_virt_offset">
      <parent link="thumb_mp2dp_virt_jointbody"/>
      <child link="thumb_dp_virt"/>
      <origin xyz="-0.0 -0.0 -0.0" rpy="0.0 0.0 0.0"/>
   </joint>
   <link name="thumb_dp">
      <inertial>
         <origin xyz="0.01561284110475684 0.006399393209142038 0.00129114363060014" rpy="-1.3841219530173001 -1.5655735717851773 -1.7640748331048437"/>
         <mass value="0.007138375295193356"/>
         <inertia ixx="8.849906238234302e-07" iyy="8.682038184958313e-07" izz="1.4921804697795188e-07" ixy="0" ixz="0" iyz="0"/>
      </inertial>
      <visual name="thumb_dp">
         <origin xyz="0.01561284110475684 0.006399393209142038 0.00129114363060014" rpy="-1.3841219530173001 -1.5655735717851773 -1.7640748331048437"/>
         <geometry>
            <mesh filename="package://dextrous_hand/data/assets/urdf/converted_thumb_dp.stl"/>
         </geometry>
         <material name="white"/>
      </visual>
   </link>
   <link name="thumb_mp2dp_jointbody">
      <inertial>
         <origin xyz="0.0 0.0 0.0" rpy="0.0 0.0 0.0"/>
         <mass value="0.001"/>
         <inertia ixx="1e-09" iyy="1e-09" izz="1e-09" ixy="0" ixz="0" iyz="0"/>
      </inertial>
   </link>
   <joint type="revolute" name="thumb_mp2dp">
      <parent link="thumb_dp_virt"/>
      <child link="thumb_mp2dp_jointbody"/>
      <origin xyz="0.012 0.0 0.0" rpy="0.0 0.0 0.0"/>
      <axis xyz="0.0 -1.0 0.0"/>
      <limit lower="0.0" upper="0.68" effort="100" velocity="100"/>
   </joint>
   <joint type="fixed" name="thumb_mp2dp_offset">
      <parent link="thumb_mp2dp_jointbody"/>
      <child link="thumb_dp"/>
      <origin xyz="-0.0 -0.0 -0.0" rpy="0.0 0.0 0.0"/>
   </joint>
   <link name="thumb_fingertip">
      <inertial>
         <origin xyz="0.03 0.0 0.0" rpy="0.0 0.0 0.0"/>
         <mass value="0.0"/>
         <inertia ixx="0.0" iyy="0.0" izz="0.0" ixy="0" ixz="0" iyz="0"/>
      </inertial>
   </link>
   <link name="thumb_dp2thumb_fingertip_fixed_jointbody">
      <inertial>
         <origin xyz="0.0 0.0 0.0" rpy="0.0 0.0 0.0"/>
         <mass value="0.001"/>
         <inertia ixx="1e-09" iyy="1e-09" izz="1e-09" ixy="0" ixz="0" iyz="0"/>
      </inertial>
   </link>
   <joint type="fixed" name="thumb_dp2thumb_fingertip_fixed">
      <parent link="thumb_dp"/>
      <child link="thumb_dp2thumb_fingertip_fixed_jointbody"/>
      <origin xyz="0.03 0.0 0.0" rpy="0.0 0.0 0.0"/>
   </joint>
   <joint type="fixed" name="thumb_dp2thumb_fingertip_fixed_offset">
      <parent link="thumb_dp2thumb_fingertip_fixed_jointbody"/>
      <child link="thumb_fingertip"/>
      <origin xyz="-0.0 -0.0 -0.0" rpy="0.0 0.0 0.0"/>
   </joint>
   <link name="index_um_virt">
      <inertial>
         <origin xyz="0.0 0.0 0.0" rpy="0.0 0.0 0.0"/>
         <mass value="0.001"/>
         <inertia ixx="4e-10" iyy="4e-10" izz="3e-10" ixy="0" ixz="0" iyz="0"/>
      </inertial>
   </link>
   <link name="index_abd_virt_jointbody">
      <inertial>
         <origin xyz="0.0 0.0 0.0" rpy="0.0 0.0 0.0"/>
         <mass value="0.001"/>
         <inertia ixx="1e-09" iyy="1e-09" izz="1e-09" ixy="0" ixz="0" iyz="0"/>
      </inertial>
   </link>
   <joint type="revolute" name="index_abd_virt">
      <parent link="palm"/>
      <child link="index_abd_virt_jointbody"/>
      <origin xyz="0.02582 0.03419 0.0075" rpy="-0.7703980049348178 1.56968716940312 0.7703980049345347"/>
      <axis xyz="1.0 0.0 0.0"/>
      <limit lower="-0.264" upper="0.264" effort="100" velocity="100"/>
   </joint>
   <link name="retarget_palm">
      <inertial>
         <origin xyz="0.0 0.0 0.0" rpy="0.0 0.0 0.0"/>
         <mass value="0.001"/>
         <inertia ixx="1e-09" iyy="1e-09" izz="1e-09" ixy="0" ixz="0" iyz="0"/>
      </inertial>
   </link>
   <joint type="fixed" name="retarget_palm_offset">
      <parent link="palm"/>
      <child link="retarget_palm"/>
      <origin xyz="-0.015 0.00 0" rpy="0 0 0"/>
   </joint>
   <joint type="fixed" name="index_abd_virt_offset">
      <parent link="index_abd_virt_jointbody"/>
      <child link="index_um_virt"/>
      <origin xyz="-0.0 -0.0 -0.0" rpy="0.0 0.0 0.0"/>
   </joint>
   <link name="index_um">
      <inertial>
         <origin xyz="0.006944011366160591 4.176827480978758e-06 -0.003113246500179754" rpy="0.0027452359923443304 -1.1834615908047053 -3.1415926535897927"/>
         <mass value="0.002101638965698638"/>
         <inertia ixx="5.415998118663882e-08" iyy="4.552933214562431e-08" izz="4.234647700133515e-08" ixy="0" ixz="0" iyz="0"/>
      </inertial>
      <visual name="index_um">
         <origin xyz="0.006944011366160591 4.176827480978758e-06 -0.003113246500179754" rpy="0.0027452359923443304 -1.1834615908047053 -3.1415926535897927"/>
         <geometry>
            <mesh filename="package://dextrous_hand/data/assets/urdf/converted_index_um.stl"/>
         </geometry>
         <material name="white"/>
      </visual>
   </link>
   <link name="index_abd_jointbody">
      <inertial>
         <origin xyz="0.0 0.0 0.0" rpy="0.0 0.0 0.0"/>
         <mass value="0.001"/>
         <inertia ixx="1e-09" iyy="1e-09" izz="1e-09" ixy="0" ixz="0" iyz="0"/>
      </inertial>
   </link>
   <joint type="revolute" name="index_abd">
      <parent link="index_um_virt"/>
      <child link="index_abd_jointbody"/>
      <origin xyz="0.0 0.0 0.018" rpy="0.0 0.0 0.0"/>
      <axis xyz="1.0 0.0 0.0"/>
      <limit lower="-0.264" upper="0.264" effort="100" velocity="100"/>
   </joint>
   <joint type="fixed" name="index_abd_offset">
      <parent link="index_abd_jointbody"/>
      <child link="index_um"/>
      <origin xyz="-0.0 -0.0 -0.0" rpy="0.0 0.0 0.0"/>
   </joint>
   <link name="index_pp_virt">
      <inertial>
         <origin xyz="0.0 0.0 0.0" rpy="0.0 0.0 0.0"/>
         <mass value="0.001"/>
         <inertia ixx="4e-10" iyy="4e-10" izz="3e-10" ixy="0" ixz="0" iyz="0"/>
      </inertial>
   </link>
   <link name="root2index_pp_virt_jointbody">
      <inertial>
         <origin xyz="0.0 0.0 0.0" rpy="0.0 0.0 0.0"/>
         <mass value="0.001"/>
         <inertia ixx="1e-09" iyy="1e-09" izz="1e-09" ixy="0" ixz="0" iyz="0"/>
      </inertial>
   </link>
   <joint type="revolute" name="root2index_pp_virt">
      <parent link="index_um"/>
      <child link="root2index_pp_virt_jointbody"/>
      <origin xyz="0.009 0.0 -0.00622" rpy="0.0 -1.57 0.0"/>
      <axis xyz="0.0 -1.0 0.0"/>
      <limit lower="-0.157" upper="0.829" effort="100" velocity="100"/>
   </joint>
   <joint type="fixed" name="root2index_pp_virt_offset">
      <parent link="root2index_pp_virt_jointbody"/>
      <child link="index_pp_virt"/>
      <origin xyz="-0.0 -0.0 -0.0" rpy="0.0 0.0 0.0"/>
   </joint>
   <link name="index_pp">
      <inertial>
         <origin xyz="0.010749754926236909 2.9135172961472633e-05 0.0013404815953176657" rpy="2.9341239748880685 -1.513655128453029 0.21008235805971665"/>
         <mass value="0.0076346354393701495"/>
         <inertia ixx="9.634233570194882e-07" iyy="9.3429336790071e-07" izz="1.7213482362040822e-07" ixy="0" ixz="0" iyz="0"/>
      </inertial>
      <visual name="index_pp">
         <origin xyz="0.010749754926236909 2.9135172961472633e-05 0.0013404815953176657" rpy="2.9341239748880685 -1.513655128453029 0.21008235805971665"/>
         <geometry>
            <mesh filename="package://dextrous_hand/data/assets/urdf/converted_index_pp.stl"/>
         </geometry>
         <material name="white"/>
      </visual>
   </link>
   <link name="root2index_pp_jointbody">
      <inertial>
         <origin xyz="0.0 0.0 0.0" rpy="0.0 0.0 0.0"/>
         <mass value="0.001"/>
         <inertia ixx="1e-09" iyy="1e-09" izz="1e-09" ixy="0" ixz="0" iyz="0"/>
      </inertial>
   </link>
   <joint type="revolute" name="root2index_pp">
      <parent link="index_pp_virt"/>
      <child link="root2index_pp_jointbody"/>
      <origin xyz="0.018 0.0 0.0" rpy="0.0 0.0 0.0"/>
      <axis xyz="0.0 -1.0 0.0"/>
      <limit lower="-0.157" upper="0.829" effort="100" velocity="100"/>
   </joint>
   <joint type="fixed" name="root2index_pp_offset">
      <parent link="root2index_pp_jointbody"/>
      <child link="index_pp"/>
      <origin xyz="-0.0 -0.0 -0.0" rpy="0.0 0.0 0.0"/>
   </joint>
   <link name="index_mp_virt">
      <inertial>
         <origin xyz="0.0 0.0 0.0" rpy="0.0 0.0 0.0"/>
         <mass value="0.001"/>
         <inertia ixx="4e-10" iyy="4e-10" izz="3e-10" ixy="0" ixz="0" iyz="0"/>
      </inertial>
   </link>
   <link name="index_pp2mp_virt_jointbody">
      <inertial>
         <origin xyz="0.0 0.0 0.0" rpy="0.0 0.0 0.0"/>
         <mass value="0.001"/>
         <inertia ixx="1e-09" iyy="1e-09" izz="1e-09" ixy="0" ixz="0" iyz="0"/>
      </inertial>
   </link>
   <joint type="revolute" name="index_pp2mp_virt">
      <parent link="index_pp"/>
      <child link="index_pp2mp_virt_jointbody"/>
      <origin xyz="0.026 0.0 -0.001" rpy="0.0 0.0 0.0"/>
      <axis xyz="0.0 -1.0 0.0"/>
      <limit lower="-0.131" upper="0.96" effort="100" velocity="100"/>
   </joint>
   <joint type="fixed" name="index_pp2mp_virt_offset">
      <parent link="index_pp2mp_virt_jointbody"/>
      <child link="index_mp_virt"/>
      <origin xyz="-0.0 -0.0 -0.0" rpy="0.0 0.0 0.0"/>
   </joint>
   <link name="index_mp">
      <inertial>
         <origin xyz="0.0075911097468111515 9.475568524443196e-06 0.0010108428021640995" rpy="-2.972353108064653 -1.5438838619161115 -0.17199888999580493"/>
         <mass value="0.0036366498908270727"/>
         <inertia ixx="2.3790060729001017e-07" iyy="2.0701944288833882e-07" izz="6.867242804840384e-08" ixy="0" ixz="0" iyz="0"/>
      </inertial>
      <visual name="index_mp">
         <origin xyz="0.0075911097468111515 9.475568524443196e-06 0.0010108428021640995" rpy="-2.9723531080646532 -1.5438838619161115 -0.1719988899958047"/>
         <geometry>
            <mesh filename="package://dextrous_hand/data/assets/urdf/converted_index_mp.stl"/>
         </geometry>
         <material name="white"/>
      </visual>
   </link>
   <link name="index_pp2mp_jointbody">
      <inertial>
         <origin xyz="0.0 0.0 0.0" rpy="0.0 0.0 0.0"/>
         <mass value="0.001"/>
         <inertia ixx="1e-09" iyy="1e-09" izz="1e-09" ixy="0" ixz="0" iyz="0"/>
      </inertial>
   </link>
   <joint type="revolute" name="index_pp2mp">
      <parent link="index_mp_virt"/>
      <child link="index_pp2mp_jointbody"/>
      <origin xyz="0.012 0.00350000102 0.0" rpy="0.0 0.0 0.0"/>
      <axis xyz="0.0 -1.0 0.0"/>
      <limit lower="-0.131" upper="0.96" effort="100" velocity="100"/>
   </joint>
   <joint type="fixed" name="index_pp2mp_offset">
      <parent link="index_pp2mp_jointbody"/>
      <child link="index_mp"/>
      <origin xyz="-0.0 -0.00350000102 -0.0" rpy="0.0 0.0 0.0"/>
   </joint>
   <link name="index_dp_virt">
      <inertial>
         <origin xyz="0.0 0.0 0.0" rpy="0.0 0.0 0.0"/>
         <mass value="0.001"/>
         <inertia ixx="4e-10" iyy="4e-10" izz="3e-10" ixy="0" ixz="0" iyz="0"/>
      </inertial>
   </link>
   <link name="index_mp2dp_virt_jointbody">
      <inertial>
         <origin xyz="0.0 0.0 0.0" rpy="0.0 0.0 0.0"/>
         <mass value="0.001"/>
         <inertia ixx="1e-09" iyy="1e-09" izz="1e-09" ixy="0" ixz="0" iyz="0"/>
      </inertial>
   </link>
   <joint type="revolute" name="index_mp2dp_virt">
      <parent link="index_mp"/>
      <child link="index_mp2dp_virt_jointbody"/>
      <origin xyz="0.017 0.00370000102 0.0" rpy="0.0 0.0 0.0"/>
      <axis xyz="0.0 -1.0 0.0"/>
      <limit lower="-0.093" upper="0.682" effort="100" velocity="100"/>
   </joint>
   <joint type="fixed" name="index_mp2dp_virt_offset">
      <parent link="index_mp2dp_virt_jointbody"/>
      <child link="index_dp_virt"/>
      <origin xyz="-0.0 -0.00370000102 -0.0" rpy="0.0 0.0 0.0"/>
   </joint>
   <link name="index_dp">
      <inertial>
         <origin xyz="0.010815464353412546 -0.0001215496767482827 0.0012896754031385832" rpy="1.5764145551207425 -1.4522812855915879 1.5560216173398569"/>
         <mass value="0.00548455016800106"/>
         <inertia ixx="3.613497835659551e-07" iyy="3.5727297003439324e-07" izz="1.1563205693695991e-07" ixy="0" ixz="0" iyz="0"/>
      </inertial>
      <visual name="index_dp">
         <origin xyz="0.010815464353412546 -0.0001215496767482827 0.0012896754031385832" rpy="1.5764145551207438 -1.4522812855915879 1.5560216173398556"/>
         <geometry>
            <mesh filename="package://dextrous_hand/data/assets/urdf/converted_index_dp.stl"/>
         </geometry>
         <material name="white"/>
      </visual>
   </link>
   <link name="index_mp2dp_jointbody">
      <inertial>
         <origin xyz="0.0 0.0 0.0" rpy="0.0 0.0 0.0"/>
         <mass value="0.001"/>
         <inertia ixx="1e-09" iyy="1e-09" izz="1e-09" ixy="0" ixz="0" iyz="0"/>
      </inertial>
   </link>
   <joint type="revolute" name="index_mp2dp">
      <parent link="index_dp_virt"/>
      <child link="index_mp2dp_jointbody"/>
      <origin xyz="0.009 0.00350000102 0.0" rpy="0.0 0.0 0.0"/>
      <axis xyz="0.0 -1.0 0.0"/>
      <limit lower="-0.093" upper="0.682" effort="100" velocity="100"/>
   </joint>
   <joint type="fixed" name="index_mp2dp_offset">
      <parent link="index_mp2dp_jointbody"/>
      <child link="index_dp"/>
      <origin xyz="-0.0 -0.00350000102 -0.0" rpy="0.0 0.0 0.0"/>
   </joint>
   <link name="index_fingertip">
      <inertial>
         <origin xyz="0.02 0.0 0.0" rpy="0.0 0.0 0.0"/>
         <mass value="0.0"/>
         <inertia ixx="0.0" iyy="0.0" izz="0.0" ixy="0" ixz="0" iyz="0"/>
      </inertial>
   </link>
   <link name="index_dp2index_fingertip_fixed_jointbody">
      <inertial>
         <origin xyz="0.0 0.0 0.0" rpy="0.0 0.0 0.0"/>
         <mass value="0.001"/>
         <inertia ixx="1e-09" iyy="1e-09" izz="1e-09" ixy="0" ixz="0" iyz="0"/>
      </inertial>
   </link>
   <joint type="fixed" name="index_dp2index_fingertip_fixed">
      <parent link="index_dp"/>
      <child link="index_dp2index_fingertip_fixed_jointbody"/>
      <origin xyz="0.02 0.0 0.0" rpy="0.0 0.0 0.0"/>
   </joint>
   <joint type="fixed" name="index_dp2index_fingertip_fixed_offset">
      <parent link="index_dp2index_fingertip_fixed_jointbody"/>
      <child link="index_fingertip"/>
      <origin xyz="-0.0 -0.0 -0.0" rpy="0.0 0.0 0.0"/>
   </joint>
   <link name="middle_um_virt">
      <inertial>
         <origin xyz="0.0 0.0 0.0" rpy="0.0 0.0 0.0"/>
         <mass value="0.001"/>
         <inertia ixx="4e-10" iyy="4e-10" izz="3e-10" ixy="0" ixz="0" iyz="0"/>
      </inertial>
   </link>
   <link name="middle_abd_virt_jointbody">
      <inertial>
         <origin xyz="0.0 0.0 0.0" rpy="0.0 0.0 0.0"/>
         <mass value="0.001"/>
         <inertia ixx="1e-09" iyy="1e-09" izz="1e-09" ixy="0" ixz="0" iyz="0"/>
      </inertial>
   </link>
   <joint type="revolute" name="middle_abd_virt">
      <parent link="palm"/>
      <child link="middle_abd_virt_jointbody"/>
      <origin xyz="0.00138 0.0353 0.0075" rpy="-0.8003980049345372 1.569653385383667 0.8003980049348112"/>
      <axis xyz="1.0 0.0 0.0"/>
      <limit lower="-0.264" upper="0.264" effort="100" velocity="100"/>
   </joint>
   <joint type="fixed" name="middle_abd_virt_offset">
      <parent link="middle_abd_virt_jointbody"/>
      <child link="middle_um_virt"/>
      <origin xyz="-0.0 -0.0 -0.0" rpy="0.0 0.0 0.0"/>
   </joint>
   <link name="middle_um">
      <inertial>
         <origin xyz="0.006944011366160591 4.176827480978758e-06 -0.003133246500179754" rpy="0.0027452359923443304 -1.1834615908047053 -3.1415926535897927"/>
         <mass value="0.002101638965698638"/>
         <inertia ixx="5.415998118663882e-08" iyy="4.552933214562431e-08" izz="4.234647700133515e-08" ixy="0" ixz="0" iyz="0"/>
      </inertial>
      <visual name="middle_um">
         <origin xyz="0.006944011366160591 4.176827480978758e-06 -0.003133246500179754" rpy="0.0027452359923443304 -1.1834615908047053 -3.1415926535897927"/>
         <geometry>
            <mesh filename="package://dextrous_hand/data/assets/urdf/converted_middle_um.stl"/>
         </geometry>
         <material name="white"/>
      </visual>
   </link>
   <link name="middle_abd_jointbody">
      <inertial>
         <origin xyz="0.0 0.0 0.0" rpy="0.0 0.0 0.0"/>
         <mass value="0.001"/>
         <inertia ixx="1e-09" iyy="1e-09" izz="1e-09" ixy="0" ixz="0" iyz="0"/>
      </inertial>
   </link>
   <joint type="revolute" name="middle_abd">
      <parent link="middle_um_virt"/>
      <child link="middle_abd_jointbody"/>
      <origin xyz="0.0 0.0 0.018" rpy="0.0 0.0 0.0"/>
      <axis xyz="1.0 0.0 0.0"/>
      <limit lower="-0.264" upper="0.264" effort="100" velocity="100"/>
   </joint>
   <joint type="fixed" name="middle_abd_offset">
      <parent link="middle_abd_jointbody"/>
      <child link="middle_um"/>
      <origin xyz="-0.0 -0.0 -0.0" rpy="0.0 0.0 0.0"/>
   </joint>
   <link name="middle_pp_virt">
      <inertial>
         <origin xyz="0.0 0.0 0.0" rpy="0.0 0.0 0.0"/>
         <mass value="0.001"/>
         <inertia ixx="4e-10" iyy="4e-10" izz="3e-10" ixy="0" ixz="0" iyz="0"/>
      </inertial>
   </link>
   <link name="root2middle_pp_virt_jointbody">
      <inertial>
         <origin xyz="0.0 0.0 0.0" rpy="0.0 0.0 0.0"/>
         <mass value="0.001"/>
         <inertia ixx="1e-09" iyy="1e-09" izz="1e-09" ixy="0" ixz="0" iyz="0"/>
      </inertial>
   </link>
   <joint type="revolute" name="root2middle_pp_virt">
      <parent link="middle_um"/>
      <child link="root2middle_pp_virt_jointbody"/>
      <origin xyz="0.009 0.002700001023199999 -0.00622" rpy="0.0 -1.57 0.0"/>
      <axis xyz="0.0 -1.0 0.0"/>
      <limit lower="-0.157" upper="0.829" effort="100" velocity="100"/>
   </joint>
   <joint type="fixed" name="root2middle_pp_virt_offset">
      <parent link="root2middle_pp_virt_jointbody"/>
      <child link="middle_pp_virt"/>
      <origin xyz="-0.0 -0.002700001023199999 -0.0" rpy="0.0 0.0 0.0"/>
   </joint>
   <link name="middle_pp">
      <inertial>
         <origin xyz="0.010749754926236909 2.9135172961472633e-05 0.0013404815953176657" rpy="2.9341239748880685 -1.513655128453029 0.21008235805971665"/>
         <mass value="0.0076346354393701495"/>
         <inertia ixx="9.634233570194882e-07" iyy="9.3429336790071e-07" izz="1.7213482362040822e-07" ixy="0" ixz="0" iyz="0"/>
      </inertial>
      <visual name="middle_pp">
         <origin xyz="0.010749754926236909 2.9135172961472633e-05 0.0013404815953176657" rpy="2.9341239748880685 -1.513655128453029 0.21008235805971665"/>
         <geometry>
            <mesh filename="package://dextrous_hand/data/assets/urdf/converted_middle_pp.stl"/>
         </geometry>
         <material name="white"/>
      </visual>
   </link>
   <link name="root2middle_pp_jointbody">
      <inertial>
         <origin xyz="0.0 0.0 0.0" rpy="0.0 0.0 0.0"/>
         <mass value="0.001"/>
         <inertia ixx="1e-09" iyy="1e-09" izz="1e-09" ixy="0" ixz="0" iyz="0"/>
      </inertial>
   </link>
   <joint type="revolute" name="root2middle_pp">
      <parent link="middle_pp_virt"/>
      <child link="root2middle_pp_jointbody"/>
      <origin xyz="0.018 0.0 0.0" rpy="0.0 0.0 0.0"/>
      <axis xyz="0.0 -1.0 0.0"/>
      <limit lower="-0.157" upper="0.829" effort="100" velocity="100"/>
   </joint>
   <joint type="fixed" name="root2middle_pp_offset">
      <parent link="root2middle_pp_jointbody"/>
      <child link="middle_pp"/>
      <origin xyz="-0.0 -0.0 -0.0" rpy="0.0 0.0 0.0"/>
   </joint>
   <link name="middle_mp_virt">
      <inertial>
         <origin xyz="0.0 0.0 0.0" rpy="0.0 0.0 0.0"/>
         <mass value="0.001"/>
         <inertia ixx="4e-10" iyy="4e-10" izz="3e-10" ixy="0" ixz="0" iyz="0"/>
      </inertial>
   </link>
   <link name="middle_pp2mp_virt_jointbody">
      <inertial>
         <origin xyz="0.0 0.0 0.0" rpy="0.0 0.0 0.0"/>
         <mass value="0.001"/>
         <inertia ixx="1e-09" iyy="1e-09" izz="1e-09" ixy="0" ixz="0" iyz="0"/>
      </inertial>
   </link>
   <joint type="revolute" name="middle_pp2mp_virt">
      <parent link="middle_pp"/>
      <child link="middle_pp2mp_virt_jointbody"/>
      <origin xyz="0.026 0.0 -0.001" rpy="0.0 0.0 0.0"/>
      <axis xyz="0.0 -1.0 0.0"/>
      <limit lower="-0.131" upper="0.96" effort="100" velocity="100"/>
   </joint>
   <joint type="fixed" name="middle_pp2mp_virt_offset">
      <parent link="middle_pp2mp_virt_jointbody"/>
      <child link="middle_mp_virt"/>
      <origin xyz="-0.0 -0.0 -0.0" rpy="0.0 0.0 0.0"/>
   </joint>
   <link name="middle_mp">
      <inertial>
         <origin xyz="0.0075911097468111515 9.475568524443196e-06 0.0010108428021640995" rpy="-2.972353108064653 -1.5438838619161115 -0.17199888999580493"/>
         <mass value="0.0036366498908270727"/>
         <inertia ixx="2.3790060729001017e-07" iyy="2.0701944288833882e-07" izz="6.867242804840384e-08" ixy="0" ixz="0" iyz="0"/>
      </inertial>
      <visual name="middle_mp">
         <origin xyz="0.0075911097468111515 9.475568524443196e-06 0.0010108428021640995" rpy="-2.9723531080646532 -1.5438838619161115 -0.1719988899958047"/>
         <geometry>
            <mesh filename="package://dextrous_hand/data/assets/urdf/converted_middle_mp.stl"/>
         </geometry>
         <material name="white"/>
      </visual>
   </link>
   <link name="middle_pp2mp_jointbody">
      <inertial>
         <origin xyz="0.0 0.0 0.0" rpy="0.0 0.0 0.0"/>
         <mass value="0.001"/>
         <inertia ixx="1e-09" iyy="1e-09" izz="1e-09" ixy="0" ixz="0" iyz="0"/>
      </inertial>
   </link>
   <joint type="revolute" name="middle_pp2mp">
      <parent link="middle_mp_virt"/>
      <child link="middle_pp2mp_jointbody"/>
      <origin xyz="0.012 0.00350000102 0.0" rpy="0.0 0.0 0.0"/>
      <axis xyz="0.0 -1.0 0.0"/>
      <limit lower="-0.131" upper="0.96" effort="100" velocity="100"/>
   </joint>
   <joint type="fixed" name="middle_pp2mp_offset">
      <parent link="middle_pp2mp_jointbody"/>
      <child link="middle_mp"/>
      <origin xyz="-0.0 -0.00350000102 -0.0" rpy="0.0 0.0 0.0"/>
   </joint>
   <link name="middle_dp_virt">
      <inertial>
         <origin xyz="0.0 0.0 0.0" rpy="0.0 0.0 0.0"/>
         <mass value="0.001"/>
         <inertia ixx="4e-10" iyy="4e-10" izz="3e-10" ixy="0" ixz="0" iyz="0"/>
      </inertial>
   </link>
   <link name="middle_mp2dp_virt_jointbody">
      <inertial>
         <origin xyz="0.0 0.0 0.0" rpy="0.0 0.0 0.0"/>
         <mass value="0.001"/>
         <inertia ixx="1e-09" iyy="1e-09" izz="1e-09" ixy="0" ixz="0" iyz="0"/>
      </inertial>
   </link>
   <joint type="revolute" name="middle_mp2dp_virt">
      <parent link="middle_mp"/>
      <child link="middle_mp2dp_virt_jointbody"/>
      <origin xyz="0.017 0.00370000102 0.0" rpy="0.0 0.0 0.0"/>
      <axis xyz="0.0 -1.0 0.0"/>
      <limit lower="-0.093" upper="0.682" effort="100" velocity="100"/>
   </joint>
   <joint type="fixed" name="middle_mp2dp_virt_offset">
      <parent link="middle_mp2dp_virt_jointbody"/>
      <child link="middle_dp_virt"/>
      <origin xyz="-0.0 -0.00370000102 -0.0" rpy="0.0 0.0 0.0"/>
   </joint>
   <link name="middle_dp">
      <inertial>
         <origin xyz="0.010815464353412546 -0.0001215496767482827 0.0012896754031385832" rpy="1.5764145551207425 -1.4522812855915879 1.5560216173398569"/>
         <mass value="0.00548455016800106"/>
         <inertia ixx="3.613497835659551e-07" iyy="3.5727297003439324e-07" izz="1.1563205693695991e-07" ixy="0" ixz="0" iyz="0"/>
      </inertial>
      <visual name="middle_dp">
         <origin xyz="0.010815464353412546 -0.0001215496767482827 0.0012896754031385832" rpy="1.5764145551207438 -1.4522812855915879 1.5560216173398556"/>
         <geometry>
            <mesh filename="package://dextrous_hand/data/assets/urdf/converted_middle_dp.stl"/>
         </geometry>
         <material name="white"/>
      </visual>
   </link>
   <link name="middle_mp2dp_jointbody">
      <inertial>
         <origin xyz="0.0 0.0 0.0" rpy="0.0 0.0 0.0"/>
         <mass value="0.001"/>
         <inertia ixx="1e-09" iyy="1e-09" izz="1e-09" ixy="0" ixz="0" iyz="0"/>
      </inertial>
   </link>
   <joint type="revolute" name="middle_mp2dp">
      <parent link="middle_dp_virt"/>
      <child link="middle_mp2dp_jointbody"/>
      <origin xyz="0.009 0.00350000102 0.0" rpy="0.0 0.0 0.0"/>
      <axis xyz="0.0 -1.0 0.0"/>
      <limit lower="-0.093" upper="0.682" effort="100" velocity="100"/>
   </joint>
   <joint type="fixed" name="middle_mp2dp_offset">
      <parent link="middle_mp2dp_jointbody"/>
      <child link="middle_dp"/>
      <origin xyz="-0.0 -0.00350000102 -0.0" rpy="0.0 0.0 0.0"/>
   </joint>
   <link name="middle_fingertip">
      <inertial>
         <origin xyz="0.02 0.0 0.0" rpy="0.0 0.0 0.0"/>
         <mass value="0.0"/>
         <inertia ixx="0.0" iyy="0.0" izz="0.0" ixy="0" ixz="0" iyz="0"/>
      </inertial>
   </link>
   <link name="middle_dp2middle_fingertip_fixed_jointbody">
      <inertial>
         <origin xyz="0.0 0.0 0.0" rpy="0.0 0.0 0.0"/>
         <mass value="0.001"/>
         <inertia ixx="1e-09" iyy="1e-09" izz="1e-09" ixy="0" ixz="0" iyz="0"/>
      </inertial>
   </link>
   <joint type="fixed" name="middle_dp2middle_fingertip_fixed">
      <parent link="middle_dp"/>
      <child link="middle_dp2middle_fingertip_fixed_jointbody"/>
      <origin xyz="0.02 0.0 0.0" rpy="0.0 0.0 0.0"/>
   </joint>
   <joint type="fixed" name="middle_dp2middle_fingertip_fixed_offset">
      <parent link="middle_dp2middle_fingertip_fixed_jointbody"/>
      <child link="middle_fingertip"/>
      <origin xyz="-0.0 -0.0 -0.0" rpy="0.0 0.0 0.0"/>
   </joint>
   <link name="ring_um_virt">
      <inertial>
         <origin xyz="0.0 0.0 0.0" rpy="0.0 0.0 0.0"/>
         <mass value="0.001"/>
         <inertia ixx="4e-10" iyy="4e-10" izz="3e-10" ixy="0" ixz="0" iyz="0"/>
      </inertial>
   </link>
   <link name="ring_abd_virt_jointbody">
      <inertial>
         <origin xyz="0.0 0.0 0.0" rpy="0.0 0.0 0.0"/>
         <mass value="0.001"/>
         <inertia ixx="1e-09" iyy="1e-09" izz="1e-09" ixy="0" ixz="0" iyz="0"/>
      </inertial>
   </link>
   <joint type="revolute" name="ring_abd_virt">
      <parent link="palm"/>
      <child link="ring_abd_virt_jointbody"/>
      <origin xyz="-0.02 0.02997 0.0075" rpy="-0.8328980055780519 1.569617947672632 0.8328980055783184"/>
      <axis xyz="1.0 0.0 0.0"/>
      <limit lower="-0.264" upper="0.264" effort="100" velocity="100"/>
   </joint>
   <joint type="fixed" name="ring_abd_virt_offset">
      <parent link="ring_abd_virt_jointbody"/>
      <child link="ring_um_virt"/>
      <origin xyz="-0.0 -0.0 -0.0" rpy="0.0 0.0 0.0"/>
   </joint>
   <link name="ring_um">
      <inertial>
         <origin xyz="0.006944011366160591 4.176827480978758e-06 -0.003133246500179754" rpy="0.0027452359923443304 -1.1834615908047053 -3.1415926535897927"/>
         <mass value="0.002101638965698638"/>
         <inertia ixx="5.415998118663882e-08" iyy="4.552933214562431e-08" izz="4.234647700133515e-08" ixy="0" ixz="0" iyz="0"/>
      </inertial>
      <visual name="ring_um">
         <origin xyz="0.006944011366160591 4.176827480978758e-06 -0.003133246500179754" rpy="0.0027452359923443304 -1.1834615908047053 -3.1415926535897927"/>
         <geometry>
            <mesh filename="package://dextrous_hand/data/assets/urdf/converted_ring_um.stl"/>
         </geometry>
         <material name="white"/>
      </visual>
   </link>
   <link name="ring_abd_jointbody">
      <inertial>
         <origin xyz="0.0 0.0 0.0" rpy="0.0 0.0 0.0"/>
         <mass value="0.001"/>
         <inertia ixx="1e-09" iyy="1e-09" izz="1e-09" ixy="0" ixz="0" iyz="0"/>
      </inertial>
   </link>
   <joint type="revolute" name="ring_abd">
      <parent link="ring_um_virt"/>
      <child link="ring_abd_jointbody"/>
      <origin xyz="0.0 0.0 0.018" rpy="0.0 0.0 0.0"/>
      <axis xyz="1.0 0.0 0.0"/>
      <limit lower="-0.264" upper="0.264" effort="100" velocity="100"/>
   </joint>
   <joint type="fixed" name="ring_abd_offset">
      <parent link="ring_abd_jointbody"/>
      <child link="ring_um"/>
      <origin xyz="-0.0 -0.0 -0.0" rpy="0.0 0.0 0.0"/>
   </joint>
   <link name="ring_pp_virt">
      <inertial>
         <origin xyz="0.0 0.0 0.0" rpy="0.0 0.0 0.0"/>
         <mass value="0.001"/>
         <inertia ixx="4e-10" iyy="4e-10" izz="3e-10" ixy="0" ixz="0" iyz="0"/>
      </inertial>
   </link>
   <link name="root2ring_pp_virt_jointbody">
      <inertial>
         <origin xyz="0.0 0.0 0.0" rpy="0.0 0.0 0.0"/>
         <mass value="0.001"/>
         <inertia ixx="1e-09" iyy="1e-09" izz="1e-09" ixy="0" ixz="0" iyz="0"/>
      </inertial>
   </link>
   <joint type="revolute" name="root2ring_pp_virt">
      <parent link="ring_um"/>
      <child link="root2ring_pp_virt_jointbody"/>
      <origin xyz="0.009 0.002700001023199999 -0.00622" rpy="0.0 -1.57 0.0"/>
      <axis xyz="0.0 -1.0 0.0"/>
      <limit lower="-0.157" upper="0.829" effort="100" velocity="100"/>
   </joint>
   <joint type="fixed" name="root2ring_pp_virt_offset">
      <parent link="root2ring_pp_virt_jointbody"/>
      <child link="ring_pp_virt"/>
      <origin xyz="-0.0 -0.002700001023199999 -0.0" rpy="0.0 0.0 0.0"/>
   </joint>
   <link name="ring_pp">
      <inertial>
         <origin xyz="0.010749754926236909 2.9135172961472633e-05 0.0013404815953176657" rpy="2.9341239748880685 -1.513655128453029 0.21008235805971665"/>
         <mass value="0.0076346354393701495"/>
         <inertia ixx="9.634233570194882e-07" iyy="9.3429336790071e-07" izz="1.7213482362040822e-07" ixy="0" ixz="0" iyz="0"/>
      </inertial>
      <visual name="ring_pp">
         <origin xyz="0.010749754926236909 2.9135172961472633e-05 0.0013404815953176657" rpy="2.9341239748880685 -1.513655128453029 0.21008235805971665"/>
         <geometry>
            <mesh filename="package://dextrous_hand/data/assets/urdf/converted_ring_pp.stl"/>
         </geometry>
         <material name="white"/>
      </visual>
   </link>
   <link name="root2ring_pp_jointbody">
      <inertial>
         <origin xyz="0.0 0.0 0.0" rpy="0.0 0.0 0.0"/>
         <mass value="0.001"/>
         <inertia ixx="1e-09" iyy="1e-09" izz="1e-09" ixy="0" ixz="0" iyz="0"/>
      </inertial>
   </link>
   <joint type="revolute" name="root2ring_pp">
      <parent link="ring_pp_virt"/>
      <child link="root2ring_pp_jointbody"/>
      <origin xyz="0.018 0.0 0.0" rpy="0.0 0.0 0.0"/>
      <axis xyz="0.0 -1.0 0.0"/>
      <limit lower="-0.157" upper="0.829" effort="100" velocity="100"/>
   </joint>
   <joint type="fixed" name="root2ring_pp_offset">
      <parent link="root2ring_pp_jointbody"/>
      <child link="ring_pp"/>
      <origin xyz="-0.0 -0.0 -0.0" rpy="0.0 0.0 0.0"/>
   </joint>
   <link name="ring_mp_virt">
      <inertial>
         <origin xyz="0.0 0.0 0.0" rpy="0.0 0.0 0.0"/>
         <mass value="0.001"/>
         <inertia ixx="4e-10" iyy="4e-10" izz="3e-10" ixy="0" ixz="0" iyz="0"/>
      </inertial>
   </link>
   <link name="ring_pp2mp_virt_jointbody">
      <inertial>
         <origin xyz="0.0 0.0 0.0" rpy="0.0 0.0 0.0"/>
         <mass value="0.001"/>
         <inertia ixx="1e-09" iyy="1e-09" izz="1e-09" ixy="0" ixz="0" iyz="0"/>
      </inertial>
   </link>
   <joint type="revolute" name="ring_pp2mp_virt">
      <parent link="ring_pp"/>
      <child link="ring_pp2mp_virt_jointbody"/>
      <origin xyz="0.026 0.0 -0.001" rpy="0.0 0.0 0.0"/>
      <axis xyz="0.0 -1.0 0.0"/>
      <limit lower="-0.131" upper="0.96" effort="100" velocity="100"/>
   </joint>
   <joint type="fixed" name="ring_pp2mp_virt_offset">
      <parent link="ring_pp2mp_virt_jointbody"/>
      <child link="ring_mp_virt"/>
      <origin xyz="-0.0 -0.0 -0.0" rpy="0.0 0.0 0.0"/>
   </joint>
   <link name="ring_mp">
      <inertial>
         <origin xyz="0.0075911097468111515 9.475568524443196e-06 0.0010108428021640995" rpy="-2.972353108064653 -1.5438838619161115 -0.17199888999580493"/>
         <mass value="0.0036366498908270727"/>
         <inertia ixx="2.3790060729001017e-07" iyy="2.0701944288833882e-07" izz="6.867242804840384e-08" ixy="0" ixz="0" iyz="0"/>
      </inertial>
      <visual name="ring_mp">
         <origin xyz="0.0075911097468111515 9.475568524443196e-06 0.0010108428021640995" rpy="-2.9723531080646532 -1.5438838619161115 -0.1719988899958047"/>
         <geometry>
            <mesh filename="package://dextrous_hand/data/assets/urdf/converted_ring_mp.stl"/>
         </geometry>
         <material name="white"/>
      </visual>
   </link>
   <link name="ring_pp2mp_jointbody">
      <inertial>
         <origin xyz="0.0 0.0 0.0" rpy="0.0 0.0 0.0"/>
         <mass value="0.001"/>
         <inertia ixx="1e-09" iyy="1e-09" izz="1e-09" ixy="0" ixz="0" iyz="0"/>
      </inertial>
   </link>
   <joint type="revolute" name="ring_pp2mp">
      <parent link="ring_mp_virt"/>
      <child link="ring_pp2mp_jointbody"/>
      <origin xyz="0.012 0.00350000102 0.0" rpy="0.0 0.0 0.0"/>
      <axis xyz="0.0 -1.0 0.0"/>
      <limit lower="-0.131" upper="0.96" effort="100" velocity="100"/>
   </joint>
   <joint type="fixed" name="ring_pp2mp_offset">
      <parent link="ring_pp2mp_jointbody"/>
      <child link="ring_mp"/>
      <origin xyz="-0.0 -0.00350000102 -0.0" rpy="0.0 0.0 0.0"/>
   </joint>
   <link name="ring_dp_virt">
      <inertial>
         <origin xyz="0.0 0.0 0.0" rpy="0.0 0.0 0.0"/>
         <mass value="0.001"/>
         <inertia ixx="4e-10" iyy="4e-10" izz="3e-10" ixy="0" ixz="0" iyz="0"/>
      </inertial>
   </link>
   <link name="ring_mp2dp_virt_jointbody">
      <inertial>
         <origin xyz="0.0 0.0 0.0" rpy="0.0 0.0 0.0"/>
         <mass value="0.001"/>
         <inertia ixx="1e-09" iyy="1e-09" izz="1e-09" ixy="0" ixz="0" iyz="0"/>
      </inertial>
   </link>
   <joint type="revolute" name="ring_mp2dp_virt">
      <parent link="ring_mp"/>
      <child link="ring_mp2dp_virt_jointbody"/>
      <origin xyz="0.017 0.00370000102 0.0" rpy="0.0 0.0 0.0"/>
      <axis xyz="0.0 -1.0 0.0"/>
      <limit lower="-0.093" upper="0.682" effort="100" velocity="100"/>
   </joint>
   <joint type="fixed" name="ring_mp2dp_virt_offset">
      <parent link="ring_mp2dp_virt_jointbody"/>
      <child link="ring_dp_virt"/>
      <origin xyz="-0.0 -0.00370000102 -0.0" rpy="0.0 0.0 0.0"/>
   </joint>
   <link name="ring_dp">
      <inertial>
         <origin xyz="0.010815464353412546 -0.0001215496767482827 0.0012896754031385832" rpy="1.5764145551207425 -1.4522812855915879 1.5560216173398569"/>
         <mass value="0.00548455016800106"/>
         <inertia ixx="3.613497835659551e-07" iyy="3.5727297003439324e-07" izz="1.1563205693695991e-07" ixy="0" ixz="0" iyz="0"/>
      </inertial>
      <visual name="ring_dp">
         <origin xyz="0.010815464353412546 -0.0001215496767482827 0.0012896754031385832" rpy="1.5764145551207438 -1.4522812855915879 1.5560216173398556"/>
         <geometry>
            <mesh filename="package://dextrous_hand/data/assets/urdf/converted_ring_dp.stl"/>
         </geometry>
         <material name="white"/>
      </visual>
   </link>
   <link name="ring_mp2dp_jointbody">
      <inertial>
         <origin xyz="0.0 0.0 0.0" rpy="0.0 0.0 0.0"/>
         <mass value="0.001"/>
         <inertia ixx="1e-09" iyy="1e-09" izz="1e-09" ixy="0" ixz="0" iyz="0"/>
      </inertial>
   </link>
   <joint type="revolute" name="ring_mp2dp">
      <parent link="ring_dp_virt"/>
      <child link="ring_mp2dp_jointbody"/>
      <origin xyz="0.009 0.00350000102 0.0" rpy="0.0 0.0 0.0"/>
      <axis xyz="0.0 -1.0 0.0"/>
      <limit lower="-0.093" upper="0.682" effort="100" velocity="100"/>
   </joint>
   <joint type="fixed" name="ring_mp2dp_offset">
      <parent link="ring_mp2dp_jointbody"/>
      <child link="ring_dp"/>
      <origin xyz="-0.0 -0.00350000102 -0.0" rpy="0.0 0.0 0.0"/>
   </joint>
   <link name="ring_fingertip">
      <inertial>
         <origin xyz="0.02 0.0 0.0" rpy="0.0 0.0 0.0"/>
         <mass value="0.0"/>
         <inertia ixx="0.0" iyy="0.0" izz="0.0" ixy="0" ixz="0" iyz="0"/>
      </inertial>
   </link>
   <link name="ring_dp2ring_fingertip_fixed_jointbody">
      <inertial>
         <origin xyz="0.0 0.0 0.0" rpy="0.0 0.0 0.0"/>
         <mass value="0.001"/>
         <inertia ixx="1e-09" iyy="1e-09" izz="1e-09" ixy="0" ixz="0" iyz="0"/>
      </inertial>
   </link>
   <joint type="fixed" name="ring_dp2ring_fingertip_fixed">
      <parent link="ring_dp"/>
      <child link="ring_dp2ring_fingertip_fixed_jointbody"/>
      <origin xyz="0.02 0.0 0.0" rpy="0.0 0.0 0.0"/>
   </joint>
   <joint type="fixed" name="ring_dp2ring_fingertip_fixed_offset">
      <parent link="ring_dp2ring_fingertip_fixed_jointbody"/>
      <child link="ring_fingertip"/>
      <origin xyz="-0.0 -0.0 -0.0" rpy="0.0 0.0 0.0"/>
   </joint>
   <link name="pinky_um_virt">
      <inertial>
         <origin xyz="0.0 0.0 0.0" rpy="0.0 0.0 0.0"/>
         <mass value="0.001"/>
         <inertia ixx="4e-10" iyy="4e-10" izz="3e-10" ixy="0" ixz="0" iyz="0"/>
      </inertial>
   </link>
   <link name="pinky_abd_virt_jointbody">
      <inertial>
         <origin xyz="0.0 0.0 0.0" rpy="0.0 0.0 0.0"/>
         <mass value="0.001"/>
         <inertia ixx="1e-09" iyy="1e-09" izz="1e-09" ixy="0" ixz="0" iyz="0"/>
      </inertial>
   </link>
   <joint type="revolute" name="pinky_abd_virt">
      <parent link="palm"/>
      <child link="pinky_abd_virt_jointbody"/>
      <origin xyz="-0.0404 0.02284 0.0075" rpy="-0.9108980098311994 1.5695380434463102 0.9108980098309498"/>
      <axis xyz="1.0 0.0 0.0"/>
      <limit lower="-0.264" upper="0.264" effort="100" velocity="100"/>
   </joint>
   <joint type="fixed" name="pinky_abd_virt_offset">
      <parent link="pinky_abd_virt_jointbody"/>
      <child link="pinky_um_virt"/>
      <origin xyz="-0.0 -0.0 -0.0" rpy="0.0 0.0 0.0"/>
   </joint>
   <link name="pinky_um">
      <inertial>
         <origin xyz="0.006944011366160591 4.176827480978758e-06 -0.003133246500179754" rpy="0.0027452359923443304 -1.1834615908047053 -3.1415926535897927"/>
         <mass value="0.002101638965698638"/>
         <inertia ixx="5.415998118663882e-08" iyy="4.552933214562431e-08" izz="4.234647700133515e-08" ixy="0" ixz="0" iyz="0"/>
      </inertial>
      <visual name="pinky_um">
         <origin xyz="0.006944011366160591 4.176827480978758e-06 -0.003133246500179754" rpy="0.0027452359923443304 -1.1834615908047053 -3.1415926535897927"/>
         <geometry>
            <mesh filename="package://dextrous_hand/data/assets/urdf/converted_pinky_um.stl"/>
         </geometry>
         <material name="white"/>
      </visual>
   </link>
   <link name="pinky_abd_jointbody">
      <inertial>
         <origin xyz="0.0 0.0 0.0" rpy="0.0 0.0 0.0"/>
         <mass value="0.001"/>
         <inertia ixx="1e-09" iyy="1e-09" izz="1e-09" ixy="0" ixz="0" iyz="0"/>
      </inertial>
   </link>
   <joint type="revolute" name="pinky_abd">
      <parent link="pinky_um_virt"/>
      <child link="pinky_abd_jointbody"/>
      <origin xyz="0.0 0.0 0.018" rpy="0.0 0.0 0.0"/>
      <axis xyz="1.0 0.0 0.0"/>
      <limit lower="-0.264" upper="0.264" effort="100" velocity="100"/>
   </joint>
   <joint type="fixed" name="pinky_abd_offset">
      <parent link="pinky_abd_jointbody"/>
      <child link="pinky_um"/>
      <origin xyz="-0.0 -0.0 -0.0" rpy="0.0 0.0 0.0"/>
   </joint>
   <link name="pinky_pp_virt">
      <inertial>
         <origin xyz="0.0 0.0 0.0" rpy="0.0 0.0 0.0"/>
         <mass value="0.001"/>
         <inertia ixx="4e-10" iyy="4e-10" izz="3e-10" ixy="0" ixz="0" iyz="0"/>
      </inertial>
   </link>
   <link name="root2pinky_pp_virt_jointbody">
      <inertial>
         <origin xyz="0.0 0.0 0.0" rpy="0.0 0.0 0.0"/>
         <mass value="0.001"/>
         <inertia ixx="1e-09" iyy="1e-09" izz="1e-09" ixy="0" ixz="0" iyz="0"/>
      </inertial>
   </link>
   <joint type="revolute" name="root2pinky_pp_virt">
      <parent link="pinky_um"/>
      <child link="root2pinky_pp_virt_jointbody"/>
      <origin xyz="0.009 0.002700001023199999 -0.00622" rpy="0.0 -1.57 0.0"/>
      <axis xyz="0.0 -1.0 0.0"/>
      <limit lower="-0.157" upper="0.829" effort="100" velocity="100"/>
   </joint>
   <joint type="fixed" name="root2pinky_pp_virt_offset">
      <parent link="root2pinky_pp_virt_jointbody"/>
      <child link="pinky_pp_virt"/>
      <origin xyz="-0.0 -0.002700001023199999 -0.0" rpy="0.0 0.0 0.0"/>
   </joint>
   <link name="pinky_pp">
      <inertial>
         <origin xyz="0.010749754926236909 2.9135172961472633e-05 0.0013404815953176657" rpy="2.9341239748880685 -1.513655128453029 0.21008235805971665"/>
         <mass value="0.0076346354393701495"/>
         <inertia ixx="9.634233570194882e-07" iyy="9.3429336790071e-07" izz="1.7213482362040822e-07" ixy="0" ixz="0" iyz="0"/>
      </inertial>
      <visual name="pinky_pp">
         <origin xyz="0.010749754926236909 2.9135172961472633e-05 0.0013404815953176657" rpy="2.9341239748880685 -1.513655128453029 0.21008235805971665"/>
         <geometry>
            <mesh filename="package://dextrous_hand/data/assets/urdf/converted_pinky_pp.stl"/>
         </geometry>
         <material name="white"/>
      </visual>
   </link>
   <link name="root2pinky_pp_jointbody">
      <inertial>
         <origin xyz="0.0 0.0 0.0" rpy="0.0 0.0 0.0"/>
         <mass value="0.001"/>
         <inertia ixx="1e-09" iyy="1e-09" izz="1e-09" ixy="0" ixz="0" iyz="0"/>
      </inertial>
   </link>
   <joint type="revolute" name="root2pinky_pp">
      <parent link="pinky_pp_virt"/>
      <child link="root2pinky_pp_jointbody"/>
      <origin xyz="0.018 0.0 0.0" rpy="0.0 0.0 0.0"/>
      <axis xyz="0.0 -1.0 0.0"/>
      <limit lower="-0.157" upper="0.829" effort="100" velocity="100"/>
   </joint>
   <joint type="fixed" name="root2pinky_pp_offset">
      <parent link="root2pinky_pp_jointbody"/>
      <child link="pinky_pp"/>
      <origin xyz="-0.0 -0.0 -0.0" rpy="0.0 0.0 0.0"/>
   </joint>
   <link name="pinky_mp_virt">
      <inertial>
         <origin xyz="0.0 0.0 0.0" rpy="0.0 0.0 0.0"/>
         <mass value="0.001"/>
         <inertia ixx="4e-10" iyy="4e-10" izz="3e-10" ixy="0" ixz="0" iyz="0"/>
      </inertial>
   </link>
   <link name="pinky_pp2mp_virt_jointbody">
      <inertial>
         <origin xyz="0.0 0.0 0.0" rpy="0.0 0.0 0.0"/>
         <mass value="0.001"/>
         <inertia ixx="1e-09" iyy="1e-09" izz="1e-09" ixy="0" ixz="0" iyz="0"/>
      </inertial>
   </link>
   <joint type="revolute" name="pinky_pp2mp_virt">
      <parent link="pinky_pp"/>
      <child link="pinky_pp2mp_virt_jointbody"/>
      <origin xyz="0.026 0.0 -0.001" rpy="0.0 0.0 0.0"/>
      <axis xyz="0.0 -1.0 0.0"/>
      <limit lower="-0.131" upper="0.96" effort="100" velocity="100"/>
   </joint>
   <joint type="fixed" name="pinky_pp2mp_virt_offset">
      <parent link="pinky_pp2mp_virt_jointbody"/>
      <child link="pinky_mp_virt"/>
      <origin xyz="-0.0 -0.0 -0.0" rpy="0.0 0.0 0.0"/>
   </joint>
   <link name="pinky_mp">
      <inertial>
         <origin xyz="0.0075911097468111515 9.475568524443196e-06 0.0010108428021640995" rpy="-2.972353108064653 -1.5438838619161115 -0.17199888999580493"/>
         <mass value="0.0036366498908270727"/>
         <inertia ixx="2.3790060729001017e-07" iyy="2.0701944288833882e-07" izz="6.867242804840384e-08" ixy="0" ixz="0" iyz="0"/>
      </inertial>
      <visual name="pinky_mp">
         <origin xyz="0.0075911097468111515 9.475568524443196e-06 0.0010108428021640995" rpy="-2.9723531080646532 -1.5438838619161115 -0.1719988899958047"/>
         <geometry>
            <mesh filename="package://dextrous_hand/data/assets/urdf/converted_pinky_mp.stl"/>
         </geometry>
         <material name="white"/>
      </visual>
   </link>
   <link name="pinky_pp2mp_jointbody">
      <inertial>
         <origin xyz="0.0 0.0 0.0" rpy="0.0 0.0 0.0"/>
         <mass value="0.001"/>
         <inertia ixx="1e-09" iyy="1e-09" izz="1e-09" ixy="0" ixz="0" iyz="0"/>
      </inertial>
   </link>
   <joint type="revolute" name="pinky_pp2mp">
      <parent link="pinky_mp_virt"/>
      <child link="pinky_pp2mp_jointbody"/>
      <origin xyz="0.012 0.00350000102 0.0" rpy="0.0 0.0 0.0"/>
      <axis xyz="0.0 -1.0 0.0"/>
      <limit lower="-0.131" upper="0.96" effort="100" velocity="100"/>
   </joint>
   <joint type="fixed" name="pinky_pp2mp_offset">
      <parent link="pinky_pp2mp_jointbody"/>
      <child link="pinky_mp"/>
      <origin xyz="-0.0 -0.00350000102 -0.0" rpy="0.0 0.0 0.0"/>
   </joint>
   <link name="pinky_dp_virt">
      <inertial>
         <origin xyz="0.0 0.0 0.0" rpy="0.0 0.0 0.0"/>
         <mass value="0.001"/>
         <inertia ixx="4e-10" iyy="4e-10" izz="3e-10" ixy="0" ixz="0" iyz="0"/>
      </inertial>
   </link>
   <link name="pinky_mp2dp_virt_jointbody">
      <inertial>
         <origin xyz="0.0 0.0 0.0" rpy="0.0 0.0 0.0"/>
         <mass value="0.001"/>
         <inertia ixx="1e-09" iyy="1e-09" izz="1e-09" ixy="0" ixz="0" iyz="0"/>
      </inertial>
   </link>
   <joint type="revolute" name="pinky_mp2dp_virt">
      <parent link="pinky_mp"/>
      <child link="pinky_mp2dp_virt_jointbody"/>
      <origin xyz="0.017 0.00370000102 0.0" rpy="0.0 0.0 0.0"/>
      <axis xyz="0.0 -1.0 0.0"/>
      <limit lower="-0.093" upper="0.682" effort="100" velocity="100"/>
   </joint>
   <joint type="fixed" name="pinky_mp2dp_virt_offset">
      <parent link="pinky_mp2dp_virt_jointbody"/>
      <child link="pinky_dp_virt"/>
      <origin xyz="-0.0 -0.00370000102 -0.0" rpy="0.0 0.0 0.0"/>
   </joint>
   <link name="pinky_dp">
      <inertial>
         <origin xyz="0.010815464353412546 -0.0001215496767482827 0.0012896754031385832" rpy="1.5764145551207425 -1.4522812855915879 1.5560216173398569"/>
         <mass value="0.00548455016800106"/>
         <inertia ixx="3.613497835659551e-07" iyy="3.5727297003439324e-07" izz="1.1563205693695991e-07" ixy="0" ixz="0" iyz="0"/>
      </inertial>
      <visual name="pinky_dp">
         <origin xyz="0.010815464353412546 -0.0001215496767482827 0.0012896754031385832" rpy="1.5764145551207438 -1.4522812855915879 1.5560216173398556"/>
         <geometry>
            <mesh filename="package://dextrous_hand/data/assets/urdf/converted_pinky_dp.stl"/>
         </geometry>
         <material name="white"/>
      </visual>
   </link>
   <link name="pinky_mp2dp_jointbody">
      <inertial>
         <origin xyz="0.0 0.0 0.0" rpy="0.0 0.0 0.0"/>
         <mass value="0.001"/>
         <inertia ixx="1e-09" iyy="1e-09" izz="1e-09" ixy="0" ixz="0" iyz="0"/>
      </inertial>
   </link>
   <joint type="revolute" name="pinky_mp2dp">
      <parent link="pinky_dp_virt"/>
      <child link="pinky_mp2dp_jointbody"/>
      <origin xyz="0.009 0.00350000102 0.0" rpy="0.0 0.0 0.0"/>
      <axis xyz="0.0 -1.0 0.0"/>
      <limit lower="-0.093" upper="0.682" effort="100" velocity="100"/>
   </joint>
   <joint type="fixed" name="pinky_mp2dp_offset">
      <parent link="pinky_mp2dp_jointbody"/>
      <child link="pinky_dp"/>
      <origin xyz="-0.0 -0.00350000102 -0.0" rpy="0.0 0.0 0.0"/>
   </joint>
   <link name="pinky_fingertip">
      <inertial>
         <origin xyz="0.02 0.0 0.0" rpy="0.0 0.0 0.0"/>
         <mass value="0.0"/>
         <inertia ixx="0.0" iyy="0.0" izz="0.0" ixy="0" ixz="0" iyz="0"/>
      </inertial>
   </link>
   <link name="pinky_dp2pinky_fingertip_fixed_jointbody">
      <inertial>
         <origin xyz="0.0 0.0 0.0" rpy="0.0 0.0 0.0"/>
         <mass value="0.001"/>
         <inertia ixx="1e-09" iyy="1e-09" izz="1e-09" ixy="0" ixz="0" iyz="0"/>
      </inertial>
   </link>
   <joint type="fixed" name="pinky_dp2pinky_fingertip_fixed">
      <parent link="pinky_dp"/>
      <child link="pinky_dp2pinky_fingertip_fixed_jointbody"/>
      <origin xyz="0.02 0.0 0.0" rpy="0.0 0.0 0.0"/>
   </joint>
   <joint type="fixed" name="pinky_dp2pinky_fingertip_fixed_offset">
      <parent link="pinky_dp2pinky_fingertip_fixed_jointbody"/>
      <child link="pinky_fingertip"/>
      <origin xyz="-0.0 -0.0 -0.0" rpy="0.0 0.0 0.0"/>
   </joint>
   <material name="white">
      <color rgba="1 1 1 1"/>
   </material>
</robot>
